2019-02-04 15:08:41,166 (12538/MainThread) pgcli.main INFO - Default pager found in PAGER environment variable: "less"
2019-02-04 15:09:14,597 (12538/MainThread) pgcli.main ERROR - traceback: 'Traceback (most recent call last):\n  File "/Users/rg/Dropbox/code/python/envs/ccat/lib/python3.7/site-packages/pgcli/main.py", line 469, in connect\n    application_name=\'pgcli\', **kwargs)\n  File "/Users/rg/Dropbox/code/python/envs/ccat/lib/python3.7/site-packages/pgcli/pgexecute.py", line 197, in __init__\n    self.connect()\n  File "/Users/rg/Dropbox/code/python/envs/ccat/lib/python3.7/site-packages/pgcli/pgexecute.py", line 239, in connect\n    **kwargs)\n  File "/Users/rg/Dropbox/code/python/envs/ccat/lib/python3.7/site-packages/psycopg2/__init__.py", line 130, in connect\n    conn = _connect(dsn, connection_factory=connection_factory, **kwasync)\n  File "/Users/rg/Dropbox/code/python/envs/ccat/lib/python3.7/site-packages/pgcli/pgexecute.py", line 40, in _wait_select\n    state = conn.poll()\npsycopg2.OperationalError: fe_sendauth: no password supplied\n\n\nDuring handling of the above exception, another exception occurred:\n\nTraceback (most recent call last):\n  File "/Users/rg/Dropbox/code/python/envs/ccat/lib/python3.7/site-packages/pgcli/main.py", line 478, in connect\n    **kwargs)\n  File "/Users/rg/Dropbox/code/python/envs/ccat/lib/python3.7/site-packages/pgcli/pgexecute.py", line 197, in __init__\n    self.connect()\n  File "/Users/rg/Dropbox/code/python/envs/ccat/lib/python3.7/site-packages/pgcli/pgexecute.py", line 239, in connect\n    **kwargs)\n  File "/Users/rg/Dropbox/code/python/envs/ccat/lib/python3.7/site-packages/psycopg2/__init__.py", line 130, in connect\n    conn = _connect(dsn, connection_factory=connection_factory, **kwasync)\n  File "/Users/rg/Dropbox/code/python/envs/ccat/lib/python3.7/site-packages/pgcli/pgexecute.py", line 40, in _wait_select\n    state = conn.poll()\npsycopg2.OperationalError: FATAL:  password authentication failed for user "postgres"\n\n'
2019-02-04 15:10:22,685 (12611/MainThread) pgcli.main INFO - Default pager found in PAGER environment variable: "less"
2019-02-04 15:10:24,413 (12611/MainThread) pgcli.main ERROR - traceback: 'Traceback (most recent call last):\n  File "/Users/rg/Dropbox/code/python/envs/ccat/lib/python3.7/site-packages/pgcli/main.py", line 469, in connect\n    application_name=\'pgcli\', **kwargs)\n  File "/Users/rg/Dropbox/code/python/envs/ccat/lib/python3.7/site-packages/pgcli/pgexecute.py", line 197, in __init__\n    self.connect()\n  File "/Users/rg/Dropbox/code/python/envs/ccat/lib/python3.7/site-packages/pgcli/pgexecute.py", line 239, in connect\n    **kwargs)\n  File "/Users/rg/Dropbox/code/python/envs/ccat/lib/python3.7/site-packages/psycopg2/__init__.py", line 130, in connect\n    conn = _connect(dsn, connection_factory=connection_factory, **kwasync)\n  File "/Users/rg/Dropbox/code/python/envs/ccat/lib/python3.7/site-packages/pgcli/pgexecute.py", line 40, in _wait_select\n    state = conn.poll()\npsycopg2.OperationalError: fe_sendauth: no password supplied\n\n\nDuring handling of the above exception, another exception occurred:\n\nTraceback (most recent call last):\n  File "/Users/rg/Dropbox/code/python/envs/ccat/lib/python3.7/site-packages/pgcli/main.py", line 478, in connect\n    **kwargs)\n  File "/Users/rg/Dropbox/code/python/envs/ccat/lib/python3.7/site-packages/pgcli/pgexecute.py", line 197, in __init__\n    self.connect()\n  File "/Users/rg/Dropbox/code/python/envs/ccat/lib/python3.7/site-packages/pgcli/pgexecute.py", line 239, in connect\n    **kwargs)\n  File "/Users/rg/Dropbox/code/python/envs/ccat/lib/python3.7/site-packages/psycopg2/__init__.py", line 130, in connect\n    conn = _connect(dsn, connection_factory=connection_factory, **kwasync)\n  File "/Users/rg/Dropbox/code/python/envs/ccat/lib/python3.7/site-packages/pgcli/pgexecute.py", line 40, in _wait_select\n    state = conn.poll()\npsycopg2.OperationalError: FATAL:  password authentication failed for user "postgres"\n\n'
2019-02-04 15:10:57,226 (12677/MainThread) pgcli.main INFO - Default pager found in PAGER environment variable: "less"
2019-02-04 15:11:04,132 (12677/MainThread) pgcli.main ERROR - traceback: 'Traceback (most recent call last):\n  File "/Users/rg/Dropbox/code/python/envs/ccat/lib/python3.7/site-packages/pgcli/main.py", line 469, in connect\n    application_name=\'pgcli\', **kwargs)\n  File "/Users/rg/Dropbox/code/python/envs/ccat/lib/python3.7/site-packages/pgcli/pgexecute.py", line 197, in __init__\n    self.connect()\n  File "/Users/rg/Dropbox/code/python/envs/ccat/lib/python3.7/site-packages/pgcli/pgexecute.py", line 239, in connect\n    **kwargs)\n  File "/Users/rg/Dropbox/code/python/envs/ccat/lib/python3.7/site-packages/psycopg2/__init__.py", line 130, in connect\n    conn = _connect(dsn, connection_factory=connection_factory, **kwasync)\n  File "/Users/rg/Dropbox/code/python/envs/ccat/lib/python3.7/site-packages/pgcli/pgexecute.py", line 40, in _wait_select\n    state = conn.poll()\npsycopg2.OperationalError: fe_sendauth: no password supplied\n\n\nDuring handling of the above exception, another exception occurred:\n\nTraceback (most recent call last):\n  File "/Users/rg/Dropbox/code/python/envs/ccat/lib/python3.7/site-packages/pgcli/main.py", line 478, in connect\n    **kwargs)\n  File "/Users/rg/Dropbox/code/python/envs/ccat/lib/python3.7/site-packages/pgcli/pgexecute.py", line 197, in __init__\n    self.connect()\n  File "/Users/rg/Dropbox/code/python/envs/ccat/lib/python3.7/site-packages/pgcli/pgexecute.py", line 239, in connect\n    **kwargs)\n  File "/Users/rg/Dropbox/code/python/envs/ccat/lib/python3.7/site-packages/psycopg2/__init__.py", line 130, in connect\n    conn = _connect(dsn, connection_factory=connection_factory, **kwasync)\n  File "/Users/rg/Dropbox/code/python/envs/ccat/lib/python3.7/site-packages/pgcli/pgexecute.py", line 40, in _wait_select\n    state = conn.poll()\npsycopg2.OperationalError: FATAL:  password authentication failed for user "postgres"\n\n'
2019-02-04 15:39:26,055 (13165/MainThread) pgcli.main INFO - Default pager found in PAGER environment variable: "less"
2019-02-04 15:39:57,215 (13165/MainThread) pgcli.pgexecute ERROR - sql: 'l', error: ProgrammingError('syntax error at or near "l"\nLINE 1: l\n        ^\n')
2019-02-04 15:39:57,217 (13165/MainThread) pgcli.pgexecute ERROR - traceback: 'Traceback (most recent call last):\n  File "/Users/rg/Dropbox/code/python/envs/ccat/lib/python3.7/site-packages/pgcli/pgexecute.py", line 357, in run\n    yield self.execute_normal_sql(sql) + (sql, True, False)\n  File "/Users/rg/Dropbox/code/python/envs/ccat/lib/python3.7/site-packages/pgcli/pgexecute.py", line 389, in execute_normal_sql\n    cur.execute(split_sql)\npsycopg2.ProgrammingError: syntax error at or near "l"\nLINE 1: l\n        ^\n\n'
2019-02-04 15:55:24,223 (13879/MainThread) pgcli.main INFO - Default pager found in PAGER environment variable: "less"
2019-02-04 15:55:26,646 (13879/MainThread) pgcli.main ERROR - traceback: 'Traceback (most recent call last):\n  File "/Users/rg/Dropbox/code/python/envs/ccat/lib/python3.7/site-packages/pgcli/main.py", line 469, in connect\n    application_name=\'pgcli\', **kwargs)\n  File "/Users/rg/Dropbox/code/python/envs/ccat/lib/python3.7/site-packages/pgcli/pgexecute.py", line 197, in __init__\n    self.connect()\n  File "/Users/rg/Dropbox/code/python/envs/ccat/lib/python3.7/site-packages/pgcli/pgexecute.py", line 239, in connect\n    **kwargs)\n  File "/Users/rg/Dropbox/code/python/envs/ccat/lib/python3.7/site-packages/psycopg2/__init__.py", line 130, in connect\n    conn = _connect(dsn, connection_factory=connection_factory, **kwasync)\n  File "/Users/rg/Dropbox/code/python/envs/ccat/lib/python3.7/site-packages/pgcli/pgexecute.py", line 40, in _wait_select\n    state = conn.poll()\npsycopg2.OperationalError: fe_sendauth: no password supplied\n\n\nDuring handling of the above exception, another exception occurred:\n\nTraceback (most recent call last):\n  File "/Users/rg/Dropbox/code/python/envs/ccat/lib/python3.7/site-packages/click/termui.py", line 100, in prompt_func\n    return f(\'\')\n  File "/Users/rg/Dropbox/code/python/envs/ccat/lib/python3.7/site-packages/click/termui.py", line 43, in hidden_prompt_func\n    return getpass.getpass(prompt)\n  File "/usr/local/Cellar/python/3.7.2_1/Frameworks/Python.framework/Versions/3.7/lib/python3.7/getpass.py", line 77, in unix_getpass\n    passwd = _raw_input(prompt, stream, input=input)\n  File "/usr/local/Cellar/python/3.7.2_1/Frameworks/Python.framework/Versions/3.7/lib/python3.7/getpass.py", line 146, in _raw_input\n    line = input.readline()\nKeyboardInterrupt\n\nDuring handling of the above exception, another exception occurred:\n\nTraceback (most recent call last):\n  File "/Users/rg/Dropbox/code/python/envs/ccat/lib/python3.7/site-packages/pgcli/main.py", line 475, in connect\n    type=str)\n  File "/Users/rg/Dropbox/code/python/envs/ccat/lib/python3.7/site-packages/click/termui.py", line 116, in prompt\n    value = prompt_func(prompt)\n  File "/Users/rg/Dropbox/code/python/envs/ccat/lib/python3.7/site-packages/click/termui.py", line 107, in prompt_func\n    raise Abort()\nclick.exceptions.Abort\n'
2019-02-04 15:55:32,575 (13892/MainThread) pgcli.main INFO - Default pager found in PAGER environment variable: "less"
2019-02-04 15:57:23,330 (13892/MainThread) pgcli.pgexecute ERROR - sql: "'d", error: ProgrammingError('unterminated quoted string at or near "\'d"\nLINE 1: \'d\n        ^\n')
2019-02-04 15:57:23,335 (13892/MainThread) pgcli.pgexecute ERROR - traceback: 'Traceback (most recent call last):\n  File "/Users/rg/Dropbox/code/python/envs/ccat/lib/python3.7/site-packages/pgcli/pgexecute.py", line 357, in run\n    yield self.execute_normal_sql(sql) + (sql, True, False)\n  File "/Users/rg/Dropbox/code/python/envs/ccat/lib/python3.7/site-packages/pgcli/pgexecute.py", line 389, in execute_normal_sql\n    cur.execute(split_sql)\npsycopg2.ProgrammingError: unterminated quoted string at or near "\'d"\nLINE 1: \'d\n        ^\n\n'
2019-02-19 13:55:48,515 (16726/MainThread) pgcli.main INFO - Default pager found in PAGER environment variable: "less"
2019-02-19 13:55:56,381 (16726/MainThread) pgcli.main ERROR - traceback: 'Traceback (most recent call last):\n  File "/Users/rg/Dropbox/_code/python/envs/ccat/lib/python3.7/site-packages/pgcli/main.py", line 469, in connect\n    application_name=\'pgcli\', **kwargs)\n  File "/Users/rg/Dropbox/_code/python/envs/ccat/lib/python3.7/site-packages/pgcli/pgexecute.py", line 197, in __init__\n    self.connect()\n  File "/Users/rg/Dropbox/_code/python/envs/ccat/lib/python3.7/site-packages/pgcli/pgexecute.py", line 239, in connect\n    **kwargs)\n  File "/Users/rg/Dropbox/_code/python/envs/ccat/lib/python3.7/site-packages/psycopg2/__init__.py", line 130, in connect\n    conn = _connect(dsn, connection_factory=connection_factory, **kwasync)\n  File "/Users/rg/Dropbox/_code/python/envs/ccat/lib/python3.7/site-packages/pgcli/pgexecute.py", line 40, in _wait_select\n    state = conn.poll()\npsycopg2.OperationalError: fe_sendauth: no password supplied\n\n\nDuring handling of the above exception, another exception occurred:\n\nTraceback (most recent call last):\n  File "/Users/rg/Dropbox/_code/python/envs/ccat/lib/python3.7/site-packages/pgcli/main.py", line 478, in connect\n    **kwargs)\n  File "/Users/rg/Dropbox/_code/python/envs/ccat/lib/python3.7/site-packages/pgcli/pgexecute.py", line 197, in __init__\n    self.connect()\n  File "/Users/rg/Dropbox/_code/python/envs/ccat/lib/python3.7/site-packages/pgcli/pgexecute.py", line 239, in connect\n    **kwargs)\n  File "/Users/rg/Dropbox/_code/python/envs/ccat/lib/python3.7/site-packages/psycopg2/__init__.py", line 130, in connect\n    conn = _connect(dsn, connection_factory=connection_factory, **kwasync)\n  File "/Users/rg/Dropbox/_code/python/envs/ccat/lib/python3.7/site-packages/pgcli/pgexecute.py", line 40, in _wait_select\n    state = conn.poll()\npsycopg2.OperationalError: FATAL:  password authentication failed for user "rg"\n\n'
2019-02-19 13:56:02,266 (16742/MainThread) pgcli.main INFO - Default pager found in PAGER environment variable: "less"
2019-02-19 13:56:14,404 (16742/MainThread) pgcli.main ERROR - traceback: 'Traceback (most recent call last):\n  File "/Users/rg/Dropbox/_code/python/envs/ccat/lib/python3.7/site-packages/pgcli/main.py", line 469, in connect\n    application_name=\'pgcli\', **kwargs)\n  File "/Users/rg/Dropbox/_code/python/envs/ccat/lib/python3.7/site-packages/pgcli/pgexecute.py", line 197, in __init__\n    self.connect()\n  File "/Users/rg/Dropbox/_code/python/envs/ccat/lib/python3.7/site-packages/pgcli/pgexecute.py", line 239, in connect\n    **kwargs)\n  File "/Users/rg/Dropbox/_code/python/envs/ccat/lib/python3.7/site-packages/psycopg2/__init__.py", line 130, in connect\n    conn = _connect(dsn, connection_factory=connection_factory, **kwasync)\n  File "/Users/rg/Dropbox/_code/python/envs/ccat/lib/python3.7/site-packages/pgcli/pgexecute.py", line 40, in _wait_select\n    state = conn.poll()\npsycopg2.OperationalError: fe_sendauth: no password supplied\n\n\nDuring handling of the above exception, another exception occurred:\n\nTraceback (most recent call last):\n  File "/Users/rg/Dropbox/_code/python/envs/ccat/lib/python3.7/site-packages/pgcli/main.py", line 478, in connect\n    **kwargs)\n  File "/Users/rg/Dropbox/_code/python/envs/ccat/lib/python3.7/site-packages/pgcli/pgexecute.py", line 197, in __init__\n    self.connect()\n  File "/Users/rg/Dropbox/_code/python/envs/ccat/lib/python3.7/site-packages/pgcli/pgexecute.py", line 239, in connect\n    **kwargs)\n  File "/Users/rg/Dropbox/_code/python/envs/ccat/lib/python3.7/site-packages/psycopg2/__init__.py", line 130, in connect\n    conn = _connect(dsn, connection_factory=connection_factory, **kwasync)\n  File "/Users/rg/Dropbox/_code/python/envs/ccat/lib/python3.7/site-packages/pgcli/pgexecute.py", line 40, in _wait_select\n    state = conn.poll()\npsycopg2.OperationalError: FATAL:  password authentication failed for user "rg"\n\n'
2019-02-19 13:56:33,357 (16757/MainThread) pgcli.main INFO - No default pager found in environment. Using os default pager
2019-02-19 13:56:57,423 (16757/MainThread) pgcli.main ERROR - traceback: 'Traceback (most recent call last):\n  File "/Users/rg/Dropbox/_code/python/envs/ccat/lib/python3.7/site-packages/pgcli/main.py", line 469, in connect\n    application_name=\'pgcli\', **kwargs)\n  File "/Users/rg/Dropbox/_code/python/envs/ccat/lib/python3.7/site-packages/pgcli/pgexecute.py", line 197, in __init__\n    self.connect()\n  File "/Users/rg/Dropbox/_code/python/envs/ccat/lib/python3.7/site-packages/pgcli/pgexecute.py", line 239, in connect\n    **kwargs)\n  File "/Users/rg/Dropbox/_code/python/envs/ccat/lib/python3.7/site-packages/psycopg2/__init__.py", line 130, in connect\n    conn = _connect(dsn, connection_factory=connection_factory, **kwasync)\n  File "/Users/rg/Dropbox/_code/python/envs/ccat/lib/python3.7/site-packages/pgcli/pgexecute.py", line 40, in _wait_select\n    state = conn.poll()\npsycopg2.OperationalError: fe_sendauth: no password supplied\n\n\nDuring handling of the above exception, another exception occurred:\n\nTraceback (most recent call last):\n  File "/Users/rg/Dropbox/_code/python/envs/ccat/lib/python3.7/site-packages/pgcli/main.py", line 478, in connect\n    **kwargs)\n  File "/Users/rg/Dropbox/_code/python/envs/ccat/lib/python3.7/site-packages/pgcli/pgexecute.py", line 197, in __init__\n    self.connect()\n  File "/Users/rg/Dropbox/_code/python/envs/ccat/lib/python3.7/site-packages/pgcli/pgexecute.py", line 239, in connect\n    **kwargs)\n  File "/Users/rg/Dropbox/_code/python/envs/ccat/lib/python3.7/site-packages/psycopg2/__init__.py", line 130, in connect\n    conn = _connect(dsn, connection_factory=connection_factory, **kwasync)\n  File "/Users/rg/Dropbox/_code/python/envs/ccat/lib/python3.7/site-packages/pgcli/pgexecute.py", line 40, in _wait_select\n    state = conn.poll()\npsycopg2.OperationalError: FATAL:  password authentication failed for user "root"\n\n'
2019-02-19 13:57:08,734 (16773/MainThread) pgcli.main INFO - Default pager found in PAGER environment variable: "less"
2019-02-19 14:09:03,806 (17701/MainThread) pgcli.main INFO - Default pager found in PAGER environment variable: "less"
2019-02-25 15:56:41,811 (2426/MainThread) pgcli.main INFO - Default pager found in PAGER environment variable: "less"
2019-02-25 15:56:48,712 (2426/MainThread) pgcli.main ERROR - traceback: 'Traceback (most recent call last):\n  File "/Users/rg/Dropbox/_code/python/envs/ccat/lib/python3.7/site-packages/pgcli/main.py", line 469, in connect\n    application_name=\'pgcli\', **kwargs)\n  File "/Users/rg/Dropbox/_code/python/envs/ccat/lib/python3.7/site-packages/pgcli/pgexecute.py", line 197, in __init__\n    self.connect()\n  File "/Users/rg/Dropbox/_code/python/envs/ccat/lib/python3.7/site-packages/pgcli/pgexecute.py", line 239, in connect\n    **kwargs)\n  File "/Users/rg/Dropbox/_code/python/envs/ccat/lib/python3.7/site-packages/psycopg2/__init__.py", line 130, in connect\n    conn = _connect(dsn, connection_factory=connection_factory, **kwasync)\n  File "/Users/rg/Dropbox/_code/python/envs/ccat/lib/python3.7/site-packages/pgcli/pgexecute.py", line 40, in _wait_select\n    state = conn.poll()\npsycopg2.OperationalError: fe_sendauth: no password supplied\n\n\nDuring handling of the above exception, another exception occurred:\n\nTraceback (most recent call last):\n  File "/Users/rg/Dropbox/_code/python/envs/ccat/lib/python3.7/site-packages/click/termui.py", line 100, in prompt_func\n    return f(\'\')\n  File "/Users/rg/Dropbox/_code/python/envs/ccat/lib/python3.7/site-packages/click/termui.py", line 43, in hidden_prompt_func\n    return getpass.getpass(prompt)\n  File "/usr/local/Cellar/python/3.7.2_1/Frameworks/Python.framework/Versions/3.7/lib/python3.7/getpass.py", line 77, in unix_getpass\n    passwd = _raw_input(prompt, stream, input=input)\n  File "/usr/local/Cellar/python/3.7.2_1/Frameworks/Python.framework/Versions/3.7/lib/python3.7/getpass.py", line 146, in _raw_input\n    line = input.readline()\nKeyboardInterrupt\n\nDuring handling of the above exception, another exception occurred:\n\nTraceback (most recent call last):\n  File "/Users/rg/Dropbox/_code/python/envs/ccat/lib/python3.7/site-packages/pgcli/main.py", line 475, in connect\n    type=str)\n  File "/Users/rg/Dropbox/_code/python/envs/ccat/lib/python3.7/site-packages/click/termui.py", line 116, in prompt\n    value = prompt_func(prompt)\n  File "/Users/rg/Dropbox/_code/python/envs/ccat/lib/python3.7/site-packages/click/termui.py", line 107, in prompt_func\n    raise Abort()\nclick.exceptions.Abort\n'
2019-02-25 15:58:19,990 (2504/MainThread) pgcli.main INFO - Default pager found in PAGER environment variable: "less"
2019-03-08 10:28:56,042 (2397/MainThread) pgcli.main INFO - Default pager found in PAGER environment variable: "less"
2019-04-23 15:25:18,291 (17379/MainThread) pgcli.main INFO - Default pager found in PAGER environment variable: "less"
2019-04-23 15:25:38,221 (17379/MainThread) pgcli.main ERROR - traceback: 'Traceback (most recent call last):\n  File "/Users/rg/Dropbox/_code/python/envs/ccat/lib/python3.7/site-packages/pgcli/main.py", line 469, in connect\n    application_name=\'pgcli\', **kwargs)\n  File "/Users/rg/Dropbox/_code/python/envs/ccat/lib/python3.7/site-packages/pgcli/pgexecute.py", line 197, in __init__\n    self.connect()\n  File "/Users/rg/Dropbox/_code/python/envs/ccat/lib/python3.7/site-packages/pgcli/pgexecute.py", line 239, in connect\n    **kwargs)\n  File "/Users/rg/Dropbox/_code/python/envs/ccat/lib/python3.7/site-packages/psycopg2/__init__.py", line 130, in connect\n    conn = _connect(dsn, connection_factory=connection_factory, **kwasync)\n  File "/Users/rg/Dropbox/_code/python/envs/ccat/lib/python3.7/site-packages/pgcli/pgexecute.py", line 40, in _wait_select\n    state = conn.poll()\npsycopg2.OperationalError: fe_sendauth: no password supplied\n\n\nDuring handling of the above exception, another exception occurred:\n\nTraceback (most recent call last):\n  File "/Users/rg/Dropbox/_code/python/envs/ccat/lib/python3.7/site-packages/click/termui.py", line 100, in prompt_func\n    return f(\'\')\n  File "/Users/rg/Dropbox/_code/python/envs/ccat/lib/python3.7/site-packages/click/termui.py", line 43, in hidden_prompt_func\n    return getpass.getpass(prompt)\n  File "/usr/local/Cellar/python/3.7.2_1/Frameworks/Python.framework/Versions/3.7/lib/python3.7/getpass.py", line 77, in unix_getpass\n    passwd = _raw_input(prompt, stream, input=input)\n  File "/usr/local/Cellar/python/3.7.2_1/Frameworks/Python.framework/Versions/3.7/lib/python3.7/getpass.py", line 146, in _raw_input\n    line = input.readline()\nKeyboardInterrupt\n\nDuring handling of the above exception, another exception occurred:\n\nTraceback (most recent call last):\n  File "/Users/rg/Dropbox/_code/python/envs/ccat/lib/python3.7/site-packages/pgcli/main.py", line 475, in connect\n    type=str)\n  File "/Users/rg/Dropbox/_code/python/envs/ccat/lib/python3.7/site-packages/click/termui.py", line 116, in prompt\n    value = prompt_func(prompt)\n  File "/Users/rg/Dropbox/_code/python/envs/ccat/lib/python3.7/site-packages/click/termui.py", line 107, in prompt_func\n    raise Abort()\nclick.exceptions.Abort\n'
2019-04-23 15:26:00,210 (17405/MainThread) pgcli.main INFO - Default pager found in PAGER environment variable: "less"
2019-05-06 15:13:16,233 (21667/MainThread) pgcli.main INFO - Default pager found in PAGER environment variable: "less"
2019-05-06 15:13:35,899 (21667/MainThread) pgcli.pgexecute ERROR - sql: "'d", error: ProgrammingError('unterminated quoted string at or near "\'d"\nLINE 1: \'d\n        ^\n')
2019-05-06 15:13:35,902 (21667/MainThread) pgcli.pgexecute ERROR - traceback: 'Traceback (most recent call last):\n  File "/Users/rg/Dropbox/_code/python/envs/ccat/lib/python3.7/site-packages/pgcli/pgexecute.py", line 357, in run\n    yield self.execute_normal_sql(sql) + (sql, True, False)\n  File "/Users/rg/Dropbox/_code/python/envs/ccat/lib/python3.7/site-packages/pgcli/pgexecute.py", line 389, in execute_normal_sql\n    cur.execute(split_sql)\npsycopg2.ProgrammingError: unterminated quoted string at or near "\'d"\nLINE 1: \'d\n        ^\n\n'
2019-05-07 12:45:15,259 (24561/MainThread) pgcli.main INFO - Default pager found in PAGER environment variable: "less"
2019-05-08 14:17:38,637 (24561/MainThread) pgcli.pgexecute ERROR - sql: 'CREATE TABLE public.timeframe_exchange\n(\n    id SERIAL PRIMARY KEY\n    timeframe_id INTEGER NOT NULL REFERENCES timeframe(id) ON UPDATE CASCADE ON DELETE CASCADE,\n    exchange_id INTEGER NOT NULL REFERENCES exchange(id) ON UPDATE CASCADE ON DELETE CASCADE,\n)', error: ProgrammingError('syntax error at or near "timeframe_id"\nLINE 4:     timeframe_id INTEGER NOT NULL REFERENCES timeframe(id) O...\n            ^\n')
2019-05-08 14:17:38,640 (24561/MainThread) pgcli.pgexecute ERROR - traceback: 'Traceback (most recent call last):\n  File "/Users/rg/Dropbox/_code/python/envs/ccat/lib/python3.7/site-packages/pgcli/pgexecute.py", line 357, in run\n    yield self.execute_normal_sql(sql) + (sql, True, False)\n  File "/Users/rg/Dropbox/_code/python/envs/ccat/lib/python3.7/site-packages/pgcli/pgexecute.py", line 389, in execute_normal_sql\n    cur.execute(split_sql)\npsycopg2.ProgrammingError: syntax error at or near "timeframe_id"\nLINE 4:     timeframe_id INTEGER NOT NULL REFERENCES timeframe(id) O...\n            ^\n\n'
2019-05-08 14:28:51,583 (24561/MainThread) pgcli.pgexecute ERROR - sql: 'SELECT\n        timeframe.id,\n        timeframe.name AS timeframe_name,\n        timeframe.miliseconds AS timeframe_miliseconds,\n        exchange.id AS exchange_id,\n        exchange.name AS exchange_name', error: ProgrammingError('missing FROM-clause entry for table "timeframe"\nLINE 2:         timeframe.id,\n                ^\n')
2019-05-08 14:28:51,584 (24561/MainThread) pgcli.pgexecute ERROR - traceback: 'Traceback (most recent call last):\n  File "/Users/rg/Dropbox/_code/python/envs/ccat/lib/python3.7/site-packages/pgcli/pgexecute.py", line 357, in run\n    yield self.execute_normal_sql(sql) + (sql, True, False)\n  File "/Users/rg/Dropbox/_code/python/envs/ccat/lib/python3.7/site-packages/pgcli/pgexecute.py", line 389, in execute_normal_sql\n    cur.execute(split_sql)\npsycopg2.ProgrammingError: missing FROM-clause entry for table "timeframe"\nLINE 2:         timeframe.id,\n                ^\n\n'
2019-05-08 14:29:24,204 (24561/MainThread) pgcli.pgexecute ERROR - sql: 'SELECT\n    timeframe.id,\n    timeframe.name AS timeframe_name,\n    timeframe.miliseconds AS timeframe_miliseconds,\n    exchange.id AS exchange_id,\n    exchange.name AS exchange_name', error: ProgrammingError('missing FROM-clause entry for table "timeframe"\nLINE 2:     timeframe.id,\n            ^\n')
2019-05-08 14:29:24,204 (24561/MainThread) pgcli.pgexecute ERROR - traceback: 'Traceback (most recent call last):\n  File "/Users/rg/Dropbox/_code/python/envs/ccat/lib/python3.7/site-packages/pgcli/pgexecute.py", line 357, in run\n    yield self.execute_normal_sql(sql) + (sql, True, False)\n  File "/Users/rg/Dropbox/_code/python/envs/ccat/lib/python3.7/site-packages/pgcli/pgexecute.py", line 389, in execute_normal_sql\n    cur.execute(split_sql)\npsycopg2.ProgrammingError: missing FROM-clause entry for table "timeframe"\nLINE 2:     timeframe.id,\n            ^\n\n'
2019-05-08 14:29:53,940 (24561/MainThread) pgcli.pgexecute ERROR - sql: 'select timeframe.id, timeframe.name', error: ProgrammingError('missing FROM-clause entry for table "timeframe"\nLINE 1: select timeframe.id, timeframe.name\n               ^\n')
2019-05-08 14:29:53,940 (24561/MainThread) pgcli.pgexecute ERROR - traceback: 'Traceback (most recent call last):\n  File "/Users/rg/Dropbox/_code/python/envs/ccat/lib/python3.7/site-packages/pgcli/pgexecute.py", line 357, in run\n    yield self.execute_normal_sql(sql) + (sql, True, False)\n  File "/Users/rg/Dropbox/_code/python/envs/ccat/lib/python3.7/site-packages/pgcli/pgexecute.py", line 389, in execute_normal_sql\n    cur.execute(split_sql)\npsycopg2.ProgrammingError: missing FROM-clause entry for table "timeframe"\nLINE 1: select timeframe.id, timeframe.name\n               ^\n\n'
2019-05-08 14:30:14,831 (24561/MainThread) pgcli.pgexecute ERROR - sql: 'SELECT \n        market.id AS market_id', error: ProgrammingError('missing FROM-clause entry for table "market"\nLINE 2:         market.id AS market_id\n                ^\n')
2019-05-08 14:30:14,831 (24561/MainThread) pgcli.pgexecute ERROR - traceback: 'Traceback (most recent call last):\n  File "/Users/rg/Dropbox/_code/python/envs/ccat/lib/python3.7/site-packages/pgcli/pgexecute.py", line 357, in run\n    yield self.execute_normal_sql(sql) + (sql, True, False)\n  File "/Users/rg/Dropbox/_code/python/envs/ccat/lib/python3.7/site-packages/pgcli/pgexecute.py", line 389, in execute_normal_sql\n    cur.execute(split_sql)\npsycopg2.ProgrammingError: missing FROM-clause entry for table "market"\nLINE 2:         market.id AS market_id\n                ^\n\n'
2019-05-08 14:37:30,681 (24561/MainThread) pgcli.pgexecute ERROR - sql: 'SELECT \n    exchange.id AS exchange_id,\n    exchange.name AS exchange_name,\n    exchange.api_key AS exchange_api_key,\n    exchange.api_secret AS exchange_api_secret,\n    timeframe.id AS timeframe_id,\n    timeframe.name AS timeframe_name,\n    timeframe.miliseconds AS timeframe_miliseconds,\nINNER JOIN exchange ON timeframe_exchange.exchange_id = exchange.id\nINNER JOIN timeframe ON timeframe_exchange.timeframe_id = timeframe.id', error: ProgrammingError('syntax error at or near "JOIN"\nLINE 9: INNER JOIN exchange ON timeframe_exchange.exchange_id = exch...\n              ^\n')
2019-05-08 14:37:30,683 (24561/MainThread) pgcli.pgexecute ERROR - traceback: 'Traceback (most recent call last):\n  File "/Users/rg/Dropbox/_code/python/envs/ccat/lib/python3.7/site-packages/pgcli/pgexecute.py", line 357, in run\n    yield self.execute_normal_sql(sql) + (sql, True, False)\n  File "/Users/rg/Dropbox/_code/python/envs/ccat/lib/python3.7/site-packages/pgcli/pgexecute.py", line 389, in execute_normal_sql\n    cur.execute(split_sql)\npsycopg2.ProgrammingError: syntax error at or near "JOIN"\nLINE 9: INNER JOIN exchange ON timeframe_exchange.exchange_id = exch...\n              ^\n\n'
2019-05-08 14:37:42,429 (24561/MainThread) pgcli.pgexecute ERROR - sql: 'SELECT \n    exchange.id AS exchange_id,\n    exchange.name AS exchange_name,\n    exchange.api_key AS exchange_api_key,\n    exchange.api_secret AS exchange_api_secret,\n    timeframe.id AS timeframe_id,\n    timeframe.name AS timeframe_name,\n    timeframe.miliseconds AS timeframe_miliseconds\nINNER JOIN exchange ON timeframe_exchange.exchange_id = exchange.id\nINNER JOIN timeframe ON timeframe_exchange.timeframe_id = timeframe.id', error: ProgrammingError('syntax error at or near "INNER"\nLINE 9: INNER JOIN exchange ON timeframe_exchange.exchange_id = exch...\n        ^\n')
2019-05-08 14:37:42,430 (24561/MainThread) pgcli.pgexecute ERROR - traceback: 'Traceback (most recent call last):\n  File "/Users/rg/Dropbox/_code/python/envs/ccat/lib/python3.7/site-packages/pgcli/pgexecute.py", line 357, in run\n    yield self.execute_normal_sql(sql) + (sql, True, False)\n  File "/Users/rg/Dropbox/_code/python/envs/ccat/lib/python3.7/site-packages/pgcli/pgexecute.py", line 389, in execute_normal_sql\n    cur.execute(split_sql)\npsycopg2.ProgrammingError: syntax error at or near "INNER"\nLINE 9: INNER JOIN exchange ON timeframe_exchange.exchange_id = exch...\n        ^\n\n'
2019-05-08 14:38:09,545 (24561/MainThread) pgcli.pgexecute ERROR - sql: 'SELECT \n    exchange.id AS exchange_id,\n    exchange.name AS exchange_name,\n    exchange.api_key AS exchange_api_key,\n    exchange.api_secret AS exchange_api_secret,\n    timeframe.id AS timeframe_id,\n    timeframe.name AS timeframe_name,\n    timeframe.miliseconds AS timeframe_miliseconds\nFROM exchange\nINNER JOIN exchange ON timeframe_exchange.exchange_id = exchange.id\nINNER JOIN timeframe ON timeframe_exchange.timeframe_id = timeframe.id', error: ProgrammingError('table name "exchange" specified more than once\n')
2019-05-08 14:38:09,545 (24561/MainThread) pgcli.pgexecute ERROR - traceback: 'Traceback (most recent call last):\n  File "/Users/rg/Dropbox/_code/python/envs/ccat/lib/python3.7/site-packages/pgcli/pgexecute.py", line 357, in run\n    yield self.execute_normal_sql(sql) + (sql, True, False)\n  File "/Users/rg/Dropbox/_code/python/envs/ccat/lib/python3.7/site-packages/pgcli/pgexecute.py", line 389, in execute_normal_sql\n    cur.execute(split_sql)\npsycopg2.ProgrammingError: table name "exchange" specified more than once\n\n'
2019-05-08 14:38:39,238 (24561/MainThread) pgcli.pgexecute ERROR - sql: 'SELECT \n    exchange.id AS exchange_id', error: ProgrammingError('missing FROM-clause entry for table "exchange"\nLINE 2:     exchange.id AS exchange_id\n            ^\n')
2019-05-08 14:38:39,239 (24561/MainThread) pgcli.pgexecute ERROR - traceback: 'Traceback (most recent call last):\n  File "/Users/rg/Dropbox/_code/python/envs/ccat/lib/python3.7/site-packages/pgcli/pgexecute.py", line 357, in run\n    yield self.execute_normal_sql(sql) + (sql, True, False)\n  File "/Users/rg/Dropbox/_code/python/envs/ccat/lib/python3.7/site-packages/pgcli/pgexecute.py", line 389, in execute_normal_sql\n    cur.execute(split_sql)\npsycopg2.ProgrammingError: missing FROM-clause entry for table "exchange"\nLINE 2:     exchange.id AS exchange_id\n            ^\n\n'
2019-05-08 14:38:53,161 (24561/MainThread) pgcli.pgexecute ERROR - sql: 'SELECT exchange.id AS exchange_id', error: ProgrammingError('missing FROM-clause entry for table "exchange"\nLINE 1: SELECT exchange.id AS exchange_id\n               ^\n')
2019-05-08 14:38:53,161 (24561/MainThread) pgcli.pgexecute ERROR - traceback: 'Traceback (most recent call last):\n  File "/Users/rg/Dropbox/_code/python/envs/ccat/lib/python3.7/site-packages/pgcli/pgexecute.py", line 357, in run\n    yield self.execute_normal_sql(sql) + (sql, True, False)\n  File "/Users/rg/Dropbox/_code/python/envs/ccat/lib/python3.7/site-packages/pgcli/pgexecute.py", line 389, in execute_normal_sql\n    cur.execute(split_sql)\npsycopg2.ProgrammingError: missing FROM-clause entry for table "exchange"\nLINE 1: SELECT exchange.id AS exchange_id\n               ^\n\n'
2019-05-08 14:39:54,627 (24561/MainThread) pgcli.pgexecute ERROR - sql: 'SELECT \n    market.id AS market_id,\n    market.symbol_native AS market_symbol_native,\n    market.symbol_ccxt AS market_symbol_ccxt,\n    market.description AS market_description,\n    exchange.id AS exchange_id,\n    exchange.name AS exchange_name,\n    exchange.api_key AS exchange_api_key,\n    exchange.api_secret AS exchange_api_secret,\n    asset_base.id AS asset_base_id,\n    asset_base.ticker AS asset_base_ticker,\n    asset_base.name AS asset_base_name,\n    asset_quote.id AS asset_quote_id,\n    asset_quote.ticker AS asset_quote_ticker,\n    asset_quote.name AS asset_quote_name,\n    pair.id AS pair_id\nFROM market', error: ProgrammingError('missing FROM-clause entry for table "exchange"\nLINE 6:     exchange.id AS exchange_id,\n            ^\n')
2019-05-08 14:39:54,627 (24561/MainThread) pgcli.pgexecute ERROR - traceback: 'Traceback (most recent call last):\n  File "/Users/rg/Dropbox/_code/python/envs/ccat/lib/python3.7/site-packages/pgcli/pgexecute.py", line 357, in run\n    yield self.execute_normal_sql(sql) + (sql, True, False)\n  File "/Users/rg/Dropbox/_code/python/envs/ccat/lib/python3.7/site-packages/pgcli/pgexecute.py", line 389, in execute_normal_sql\n    cur.execute(split_sql)\npsycopg2.ProgrammingError: missing FROM-clause entry for table "exchange"\nLINE 6:     exchange.id AS exchange_id,\n            ^\n\n'
2019-05-08 14:40:17,969 (24561/MainThread) pgcli.pgexecute ERROR - sql: 'SELECT \n    market.id AS market_id,\n    market.symbol_native AS market_symbol_native,\n    market.symbol_ccxt AS market_symbol_ccxt,\n    market.description AS market_description', error: ProgrammingError('missing FROM-clause entry for table "market"\nLINE 2:     market.id AS market_id,\n            ^\n')
2019-05-08 14:40:17,970 (24561/MainThread) pgcli.pgexecute ERROR - traceback: 'Traceback (most recent call last):\n  File "/Users/rg/Dropbox/_code/python/envs/ccat/lib/python3.7/site-packages/pgcli/pgexecute.py", line 357, in run\n    yield self.execute_normal_sql(sql) + (sql, True, False)\n  File "/Users/rg/Dropbox/_code/python/envs/ccat/lib/python3.7/site-packages/pgcli/pgexecute.py", line 389, in execute_normal_sql\n    cur.execute(split_sql)\npsycopg2.ProgrammingError: missing FROM-clause entry for table "market"\nLINE 2:     market.id AS market_id,\n            ^\n\n'
2019-05-08 14:40:44,763 (24561/MainThread) pgcli.pgexecute ERROR - sql: 'SELECT \n    exchange.id AS exchange_id,\n    exchange.name AS exchange_name,\n    exchange.api_key AS exchange_api_key,\n    exchange.api_secret AS exchange_api_secret,\n    timeframe.id AS timeframe_id,\n    timeframe.name AS timeframe_name,\n    timeframe.miliseconds AS timeframe_miliseconds\nFROM exchange', error: ProgrammingError('missing FROM-clause entry for table "timeframe"\nLINE 6:     timeframe.id AS timeframe_id,\n            ^\n')
2019-05-08 14:40:44,763 (24561/MainThread) pgcli.pgexecute ERROR - traceback: 'Traceback (most recent call last):\n  File "/Users/rg/Dropbox/_code/python/envs/ccat/lib/python3.7/site-packages/pgcli/pgexecute.py", line 357, in run\n    yield self.execute_normal_sql(sql) + (sql, True, False)\n  File "/Users/rg/Dropbox/_code/python/envs/ccat/lib/python3.7/site-packages/pgcli/pgexecute.py", line 389, in execute_normal_sql\n    cur.execute(split_sql)\npsycopg2.ProgrammingError: missing FROM-clause entry for table "timeframe"\nLINE 6:     timeframe.id AS timeframe_id,\n            ^\n\n'
2019-05-08 14:42:27,877 (24561/MainThread) pgcli.pgexecute ERROR - sql: 'select exchange.id, timeframe.id from exchange', error: ProgrammingError('missing FROM-clause entry for table "timeframe"\nLINE 1: select exchange.id, timeframe.id from exchange\n                            ^\n')
2019-05-08 14:42:27,877 (24561/MainThread) pgcli.pgexecute ERROR - traceback: 'Traceback (most recent call last):\n  File "/Users/rg/Dropbox/_code/python/envs/ccat/lib/python3.7/site-packages/pgcli/pgexecute.py", line 357, in run\n    yield self.execute_normal_sql(sql) + (sql, True, False)\n  File "/Users/rg/Dropbox/_code/python/envs/ccat/lib/python3.7/site-packages/pgcli/pgexecute.py", line 389, in execute_normal_sql\n    cur.execute(split_sql)\npsycopg2.ProgrammingError: missing FROM-clause entry for table "timeframe"\nLINE 1: select exchange.id, timeframe.id from exchange\n                            ^\n\n'
2019-05-08 14:44:19,340 (24561/MainThread) pgcli.pgexecute ERROR - sql: 'select exchange.id, timeframe.id from exchange INNER JOIN exchange ON timeframe_exchange.exchange_id = exchange.id', error: ProgrammingError('table name "exchange" specified more than once\n')
2019-05-08 14:44:19,341 (24561/MainThread) pgcli.pgexecute ERROR - traceback: 'Traceback (most recent call last):\n  File "/Users/rg/Dropbox/_code/python/envs/ccat/lib/python3.7/site-packages/pgcli/pgexecute.py", line 357, in run\n    yield self.execute_normal_sql(sql) + (sql, True, False)\n  File "/Users/rg/Dropbox/_code/python/envs/ccat/lib/python3.7/site-packages/pgcli/pgexecute.py", line 389, in execute_normal_sql\n    cur.execute(split_sql)\npsycopg2.ProgrammingError: table name "exchange" specified more than once\n\n'
2019-05-08 15:01:53,372 (24561/MainThread) pgcli.pgexecute ERROR - sql: 'SELECT \n    exchange.id AS exchange_id,\n    exchange.name AS exchange_name,\n    exchange.api_key AS exchange_api_key,\n    exchange.api_secret AS exchange_api_secret,\n    timeframe.id AS timeframe_id,\n    timeframe.name AS timeframe_name,\n    timeframe.miliseconds AS timeframe_miliseconds\nFROM exchange, timeframe', error: ProgrammingError('column timeframe.miliseconds does not exist\nLINE 8:     timeframe.miliseconds AS timeframe_miliseconds\n            ^\nHINT:  Perhaps you meant to reference the column "timeframe.milliseconds".\n')
2019-05-08 15:01:53,373 (24561/MainThread) pgcli.pgexecute ERROR - traceback: 'Traceback (most recent call last):\n  File "/Users/rg/Dropbox/_code/python/envs/ccat/lib/python3.7/site-packages/pgcli/pgexecute.py", line 357, in run\n    yield self.execute_normal_sql(sql) + (sql, True, False)\n  File "/Users/rg/Dropbox/_code/python/envs/ccat/lib/python3.7/site-packages/pgcli/pgexecute.py", line 389, in execute_normal_sql\n    cur.execute(split_sql)\npsycopg2.ProgrammingError: column timeframe.miliseconds does not exist\nLINE 8:     timeframe.miliseconds AS timeframe_miliseconds\n            ^\nHINT:  Perhaps you meant to reference the column "timeframe.milliseconds".\n\n'
2019-05-08 15:02:49,199 (24561/MainThread) pgcli.pgexecute ERROR - sql: 'SELECT \n    exchange.id AS exchange_id,\n    exchange.name AS exchange_name,\n    exchange.api_key AS exchange_api_key,\n    exchange.api_secret AS exchange_api_secret,\n    timeframe.id AS timeframe_id,\n    timeframe.name AS timeframe_name,\n    timeframe.milliseconds AS timeframe_milliseconds\nFROM exchange, timeframe\nINNER JOIN exchange ON timeframe_exchange.exchange_id = exchange.id\nINNER JOIN timeframe ON timeframe_exchange.timeframe_id = timeframe.id', error: ProgrammingError('missing FROM-clause entry for table "timeframe_exchange"\nLINE 10: INNER JOIN exchange ON timeframe_exchange.exchange_id = exch...\n                                ^\n')
2019-05-08 15:02:49,199 (24561/MainThread) pgcli.pgexecute ERROR - traceback: 'Traceback (most recent call last):\n  File "/Users/rg/Dropbox/_code/python/envs/ccat/lib/python3.7/site-packages/pgcli/pgexecute.py", line 357, in run\n    yield self.execute_normal_sql(sql) + (sql, True, False)\n  File "/Users/rg/Dropbox/_code/python/envs/ccat/lib/python3.7/site-packages/pgcli/pgexecute.py", line 389, in execute_normal_sql\n    cur.execute(split_sql)\npsycopg2.ProgrammingError: missing FROM-clause entry for table "timeframe_exchange"\nLINE 10: INNER JOIN exchange ON timeframe_exchange.exchange_id = exch...\n                                ^\n\n'
2019-05-08 15:03:50,716 (24561/MainThread) pgcli.pgexecute ERROR - sql: 'SELECT \n    exchange.id AS exchange_id,\n    exchange.name AS exchange_name,\n    exchange.api_key AS exchange_api_key,\n    exchange.api_secret AS exchange_api_secret,\n    timeframe.id AS timeframe_id,\n    timeframe.name AS timeframe_name,\n    timeframe.milliseconds AS timeframe_milliseconds,\n    timeframe_exchange.id AS timeframe_exchange_id\nFROM exchange, timeframe, timeframe_exchange\nINNER JOIN exchange ON timeframe_exchange.exchange_id = exchange.id\nINNER JOIN timeframe ON timeframe_exchange.timeframe_id = timeframe.id', error: ProgrammingError('table name "exchange" specified more than once\n')
2019-05-08 15:03:50,716 (24561/MainThread) pgcli.pgexecute ERROR - traceback: 'Traceback (most recent call last):\n  File "/Users/rg/Dropbox/_code/python/envs/ccat/lib/python3.7/site-packages/pgcli/pgexecute.py", line 357, in run\n    yield self.execute_normal_sql(sql) + (sql, True, False)\n  File "/Users/rg/Dropbox/_code/python/envs/ccat/lib/python3.7/site-packages/pgcli/pgexecute.py", line 389, in execute_normal_sql\n    cur.execute(split_sql)\npsycopg2.ProgrammingError: table name "exchange" specified more than once\n\n'
2019-05-08 15:05:15,047 (24561/MainThread) pgcli.pgexecute ERROR - sql: 'SELECT \n    timeframe_exchange.id AS timeframe_exchange_id,\n    timeframe.id AS timeframe_id,\n    timeframe.name AS timeframe_name,\n    timeframe.milliseconds AS timeframe_milliseconds,\n    exchange.id AS exchange_id,\n    exchange.name AS exchange_name,\n    exchange.api_key AS exchange_api_key,\n    exchange.api_secret AS exchange_api_secret,\nFROM timeframe_exchange\nINNER JOIN exchange ON timeframe_exchange.exchange_id = exchange.id\nINNER JOIN timeframe ON timeframe_exchange.timeframe_id = timeframe.id', error: ProgrammingError('syntax error at or near "FROM"\nLINE 10: FROM timeframe_exchange\n         ^\n')
2019-05-08 15:05:15,048 (24561/MainThread) pgcli.pgexecute ERROR - traceback: 'Traceback (most recent call last):\n  File "/Users/rg/Dropbox/_code/python/envs/ccat/lib/python3.7/site-packages/pgcli/pgexecute.py", line 357, in run\n    yield self.execute_normal_sql(sql) + (sql, True, False)\n  File "/Users/rg/Dropbox/_code/python/envs/ccat/lib/python3.7/site-packages/pgcli/pgexecute.py", line 389, in execute_normal_sql\n    cur.execute(split_sql)\npsycopg2.ProgrammingError: syntax error at or near "FROM"\nLINE 10: FROM timeframe_exchange\n         ^\n\n'
2019-05-08 15:06:48,155 (24561/MainThread) pgcli.pgexecute ERROR - sql: 'DROP VIEW public.timeframe_exchange', error: ProgrammingError('"timeframe_exchange" is not a view\nHINT:  Use DROP TABLE to remove a table.\n')
2019-05-08 15:06:48,155 (24561/MainThread) pgcli.pgexecute ERROR - traceback: 'Traceback (most recent call last):\n  File "/Users/rg/Dropbox/_code/python/envs/ccat/lib/python3.7/site-packages/pgcli/pgexecute.py", line 357, in run\n    yield self.execute_normal_sql(sql) + (sql, True, False)\n  File "/Users/rg/Dropbox/_code/python/envs/ccat/lib/python3.7/site-packages/pgcli/pgexecute.py", line 389, in execute_normal_sql\n    cur.execute(split_sql)\npsycopg2.ProgrammingError: "timeframe_exchange" is not a view\nHINT:  Use DROP TABLE to remove a table.\n\n'
2019-05-08 15:07:21,975 (24561/MainThread) pgcli.pgexecute ERROR - sql: 'CREATE OR REPLACE VIEW public timeframe_exchange AS\nSELECT\n    timeframe_exchange.id AS timeframe_exchange_id,\n    timeframe.id AS timeframe_id,\n    timeframe.name AS timeframe_name,\n    timeframe.milliseconds AS timeframe_milliseconds,\n    exchange.id AS exchange_id,\n    exchange.name AS exchange_name\nFROM timeframe_exchange\nINNER JOIN exchange ON timeframe_exchange.exchange_id = exchange.id\nINNER JOIN timeframe ON timeframe_exchange.timeframe_id = timeframe.id', error: ProgrammingError('syntax error at or near "timeframe_exchange"\nLINE 1: CREATE OR REPLACE VIEW public timeframe_exchange AS\n                                      ^\n')
2019-05-08 15:07:21,977 (24561/MainThread) pgcli.pgexecute ERROR - traceback: 'Traceback (most recent call last):\n  File "/Users/rg/Dropbox/_code/python/envs/ccat/lib/python3.7/site-packages/pgcli/pgexecute.py", line 357, in run\n    yield self.execute_normal_sql(sql) + (sql, True, False)\n  File "/Users/rg/Dropbox/_code/python/envs/ccat/lib/python3.7/site-packages/pgcli/pgexecute.py", line 389, in execute_normal_sql\n    cur.execute(split_sql)\npsycopg2.ProgrammingError: syntax error at or near "timeframe_exchange"\nLINE 1: CREATE OR REPLACE VIEW public timeframe_exchange AS\n                                      ^\n\n'
2019-05-08 15:07:35,792 (24561/MainThread) pgcli.pgexecute ERROR - sql: 'CREATE OR REPLACE VIEW public.timeframe_exchange AS\nSELECT\n    timeframe_exchange.id AS timeframe_exchange_id,\n    timeframe.id AS timeframe_id,\n    timeframe.name AS timeframe_name,\n    timeframe.milliseconds AS timeframe_milliseconds,\n    exchange.id AS exchange_id,\n    exchange.name AS exchange_name\nFROM timeframe_exchange\nINNER JOIN exchange ON timeframe_exchange.exchange_id = exchange.id\nINNER JOIN timeframe ON timeframe_exchange.timeframe_id = timeframe.id', error: ProgrammingError('"timeframe_exchange" is not a view\n')
2019-05-08 15:07:35,792 (24561/MainThread) pgcli.pgexecute ERROR - traceback: 'Traceback (most recent call last):\n  File "/Users/rg/Dropbox/_code/python/envs/ccat/lib/python3.7/site-packages/pgcli/pgexecute.py", line 357, in run\n    yield self.execute_normal_sql(sql) + (sql, True, False)\n  File "/Users/rg/Dropbox/_code/python/envs/ccat/lib/python3.7/site-packages/pgcli/pgexecute.py", line 389, in execute_normal_sql\n    cur.execute(split_sql)\npsycopg2.ProgrammingError: "timeframe_exchange" is not a view\n\n'
2019-05-08 15:41:17,561 (24561/MainThread) pgcli.pgexecute ERROR - sql: 'exchange.id AS exchange_id,\n    exchange.name AS exchange_name,\n    exchange.api_key AS exchange_api_key,\n    exchange.api_secret AS exchange_api_secret,\n    timeframe.id AS timeframe_id,\n    timeframe.name AS timeframe_name,\n    timeframe.milliseconds AS timeframe_milliseconds\nFROM exchange, timeframe\nINNER JOIN exchange ON timeframe_exchange.exchange_id = exchange.id\nINNER JOIN timeframe ON timeframe_exchange.timeframe_id = timeframe.id', error: ProgrammingError('syntax error at or near "exchange"\nLINE 1: exchange.id AS exchange_id,\n        ^\n')
2019-05-08 15:41:17,562 (24561/MainThread) pgcli.pgexecute ERROR - traceback: 'Traceback (most recent call last):\n  File "/Users/rg/Dropbox/_code/python/envs/ccat/lib/python3.7/site-packages/pgcli/pgexecute.py", line 357, in run\n    yield self.execute_normal_sql(sql) + (sql, True, False)\n  File "/Users/rg/Dropbox/_code/python/envs/ccat/lib/python3.7/site-packages/pgcli/pgexecute.py", line 389, in execute_normal_sql\n    cur.execute(split_sql)\npsycopg2.ProgrammingError: syntax error at or near "exchange"\nLINE 1: exchange.id AS exchange_id,\n        ^\n\n'
2019-05-08 15:51:20,270 (24561/MainThread) pgcli.pgexecute ERROR - sql: 'SELECT * FROM buckets USING buckets b2\nWHERE buckets.market_id = b2.market_id AND buckets.timeframe_id = b2.timeframe_id AND buckets.time_close = b2.time_close AND buckets.id < b2.id', error: ProgrammingError('syntax error at or near "USING"\nLINE 1: SELECT * FROM buckets USING buckets b2\n                              ^\n')
2019-05-08 15:51:20,271 (24561/MainThread) pgcli.pgexecute ERROR - traceback: 'Traceback (most recent call last):\n  File "/Users/rg/Dropbox/_code/python/envs/ccat/lib/python3.7/site-packages/pgcli/pgexecute.py", line 357, in run\n    yield self.execute_normal_sql(sql) + (sql, True, False)\n  File "/Users/rg/Dropbox/_code/python/envs/ccat/lib/python3.7/site-packages/pgcli/pgexecute.py", line 389, in execute_normal_sql\n    cur.execute(split_sql)\npsycopg2.ProgrammingError: syntax error at or near "USING"\nLINE 1: SELECT * FROM buckets USING buckets b2\n                              ^\n\n'
2019-05-08 15:56:48,312 (24561/MainThread) pgcli.pgexecute ERROR - sql: 'DELETE FROM buckets USING buckets b2\n  WHERE buckets.market_id = b2.market_id AND buckets.timeframe_id = b2.timeframe_id AND buckets.time_close = b2.time_close AND buckets.id < b2.id', error: ProgrammingError('relation "buckets" does not exist\nLINE 1: DELETE FROM buckets USING buckets b2\n                    ^\n')
2019-05-08 15:56:48,313 (24561/MainThread) pgcli.pgexecute ERROR - traceback: 'Traceback (most recent call last):\n  File "/Users/rg/Dropbox/_code/python/envs/ccat/lib/python3.7/site-packages/pgcli/pgexecute.py", line 357, in run\n    yield self.execute_normal_sql(sql) + (sql, True, False)\n  File "/Users/rg/Dropbox/_code/python/envs/ccat/lib/python3.7/site-packages/pgcli/pgexecute.py", line 389, in execute_normal_sql\n    cur.execute(split_sql)\npsycopg2.ProgrammingError: relation "buckets" does not exist\nLINE 1: DELETE FROM buckets USING buckets b2\n                    ^\n\n'
2019-06-07 13:48:12,928 (23376/MainThread) pgcli.main INFO - Default pager found in PAGER environment variable: "less"
2019-06-07 13:48:38,902 (23376/MainThread) pgcli.main ERROR - traceback: 'Traceback (most recent call last):\n  File "/Users/rg/Dropbox/_code/python/envs/ccat_w_jupyter/lib/python3.7/site-packages/pgcli/main.py", line 469, in connect\n    application_name=\'pgcli\', **kwargs)\n  File "/Users/rg/Dropbox/_code/python/envs/ccat_w_jupyter/lib/python3.7/site-packages/pgcli/pgexecute.py", line 197, in __init__\n    self.connect()\n  File "/Users/rg/Dropbox/_code/python/envs/ccat_w_jupyter/lib/python3.7/site-packages/pgcli/pgexecute.py", line 239, in connect\n    **kwargs)\n  File "/Users/rg/Dropbox/_code/python/envs/ccat_w_jupyter/lib/python3.7/site-packages/psycopg2/__init__.py", line 130, in connect\n    conn = _connect(dsn, connection_factory=connection_factory, **kwasync)\n  File "/Users/rg/Dropbox/_code/python/envs/ccat_w_jupyter/lib/python3.7/site-packages/pgcli/pgexecute.py", line 40, in _wait_select\n    state = conn.poll()\npsycopg2.OperationalError: fe_sendauth: no password supplied\n\n\nDuring handling of the above exception, another exception occurred:\n\nTraceback (most recent call last):\n  File "/Users/rg/Dropbox/_code/python/envs/ccat_w_jupyter/lib/python3.7/site-packages/pgcli/main.py", line 478, in connect\n    **kwargs)\n  File "/Users/rg/Dropbox/_code/python/envs/ccat_w_jupyter/lib/python3.7/site-packages/pgcli/pgexecute.py", line 197, in __init__\n    self.connect()\n  File "/Users/rg/Dropbox/_code/python/envs/ccat_w_jupyter/lib/python3.7/site-packages/pgcli/pgexecute.py", line 239, in connect\n    **kwargs)\n  File "/Users/rg/Dropbox/_code/python/envs/ccat_w_jupyter/lib/python3.7/site-packages/psycopg2/__init__.py", line 130, in connect\n    conn = _connect(dsn, connection_factory=connection_factory, **kwasync)\n  File "/Users/rg/Dropbox/_code/python/envs/ccat_w_jupyter/lib/python3.7/site-packages/pgcli/pgexecute.py", line 40, in _wait_select\n    state = conn.poll()\npsycopg2.OperationalError: FATAL:  password authentication failed for user "postgres"\n\n'
2019-06-07 13:48:40,738 (23395/MainThread) pgcli.main INFO - Default pager found in PAGER environment variable: "less"
2019-06-07 13:50:15,418 (23395/MainThread) pgcli.pgexecute ERROR - sql: 'create table public.order', error: ProgrammingError('syntax error at end of input\nLINE 1: create table public.order\n                                 ^\n')
2019-06-07 13:50:15,420 (23395/MainThread) pgcli.pgexecute ERROR - traceback: 'Traceback (most recent call last):\n  File "/Users/rg/Dropbox/_code/python/envs/ccat_w_jupyter/lib/python3.7/site-packages/pgcli/pgexecute.py", line 357, in run\n    yield self.execute_normal_sql(sql) + (sql, True, False)\n  File "/Users/rg/Dropbox/_code/python/envs/ccat_w_jupyter/lib/python3.7/site-packages/pgcli/pgexecute.py", line 389, in execute_normal_sql\n    cur.execute(split_sql)\npsycopg2.ProgrammingError: syntax error at end of input\nLINE 1: create table public.order\n                                 ^\n\n'
2019-06-07 13:50:21,698 (23395/MainThread) pgcli.pgexecute ERROR - sql: 'create table public.order', error: ProgrammingError('syntax error at end of input\nLINE 1: create table public.order\n                                 ^\n')
2019-06-07 13:50:21,699 (23395/MainThread) pgcli.pgexecute ERROR - traceback: 'Traceback (most recent call last):\n  File "/Users/rg/Dropbox/_code/python/envs/ccat_w_jupyter/lib/python3.7/site-packages/pgcli/pgexecute.py", line 357, in run\n    yield self.execute_normal_sql(sql) + (sql, True, False)\n  File "/Users/rg/Dropbox/_code/python/envs/ccat_w_jupyter/lib/python3.7/site-packages/pgcli/pgexecute.py", line 389, in execute_normal_sql\n    cur.execute(split_sql)\npsycopg2.ProgrammingError: syntax error at end of input\nLINE 1: create table public.order\n                                 ^\n\n'
2019-06-07 13:50:33,893 (23395/MainThread) pgcli.pgexecute ERROR - sql: 'create table public.order', error: ProgrammingError('syntax error at end of input\nLINE 1: create table public.order\n                                 ^\n')
2019-06-07 13:50:33,894 (23395/MainThread) pgcli.pgexecute ERROR - traceback: 'Traceback (most recent call last):\n  File "/Users/rg/Dropbox/_code/python/envs/ccat_w_jupyter/lib/python3.7/site-packages/pgcli/pgexecute.py", line 357, in run\n    yield self.execute_normal_sql(sql) + (sql, True, False)\n  File "/Users/rg/Dropbox/_code/python/envs/ccat_w_jupyter/lib/python3.7/site-packages/pgcli/pgexecute.py", line 389, in execute_normal_sql\n    cur.execute(split_sql)\npsycopg2.ProgrammingError: syntax error at end of input\nLINE 1: create table public.order\n                                 ^\n\n'
2019-07-02 14:38:44,635 (61608/MainThread) pgcli.main INFO - Default pager found in PAGER environment variable: "less"
2019-07-02 14:38:44,635 (61608/MainThread) pgcli.main WARNING - import keyring failed: ModuleNotFoundError("No module named 'keyring'").
2019-07-02 14:41:35,501 (61646/MainThread) pgcli.main INFO - Default pager found in PAGER environment variable: "less"
2019-07-02 14:41:35,502 (61646/MainThread) pgcli.main WARNING - import keyring failed: ModuleNotFoundError("No module named 'keyring'").
2019-08-07 15:59:59,759 (5694/MainThread) pgcli.main INFO - Default pager found in PAGER environment variable: "less"
2019-08-07 15:59:59,760 (5694/MainThread) pgcli.main WARNING - import keyring failed: ModuleNotFoundError("No module named 'keyring'").
2019-08-07 16:00:20,465 (5694/MainThread) pgcli.main ERROR - traceback: 'Traceback (most recent call last):\n  File "/Users/rg/Dropbox/_code/python/envs/ccat_w_jupyter/lib/python3.7/site-packages/pgcli/main.py", line 556, in connect\n    pgexecute = PGExecute(database, user, passwd, host, port, dsn, **kwargs)\n  File "/Users/rg/Dropbox/_code/python/envs/ccat_w_jupyter/lib/python3.7/site-packages/pgcli/pgexecute.py", line 215, in __init__\n    self.connect(database, user, password, host, port, dsn, **kwargs)\n  File "/Users/rg/Dropbox/_code/python/envs/ccat_w_jupyter/lib/python3.7/site-packages/pgcli/pgexecute.py", line 267, in connect\n    conn = psycopg2.connect(**conn_params)\n  File "/Users/rg/Dropbox/_code/python/envs/ccat_w_jupyter/lib/python3.7/site-packages/psycopg2/__init__.py", line 126, in connect\n    conn = _connect(dsn, connection_factory=connection_factory, **kwasync)\n  File "/Users/rg/Dropbox/_code/python/envs/ccat_w_jupyter/lib/python3.7/site-packages/pgcli/pgexecute.py", line 40, in _wait_select\n    state = conn.poll()\npsycopg2.OperationalError: fe_sendauth: no password supplied\n\n\nDuring handling of the above exception, another exception occurred:\n\nTraceback (most recent call last):\n  File "/Users/rg/Dropbox/_code/python/envs/ccat_w_jupyter/lib/python3.7/site-packages/pgcli/main.py", line 566, in connect\n    database, user, passwd, host, port, dsn, **kwargs\n  File "/Users/rg/Dropbox/_code/python/envs/ccat_w_jupyter/lib/python3.7/site-packages/pgcli/pgexecute.py", line 215, in __init__\n    self.connect(database, user, password, host, port, dsn, **kwargs)\n  File "/Users/rg/Dropbox/_code/python/envs/ccat_w_jupyter/lib/python3.7/site-packages/pgcli/pgexecute.py", line 267, in connect\n    conn = psycopg2.connect(**conn_params)\n  File "/Users/rg/Dropbox/_code/python/envs/ccat_w_jupyter/lib/python3.7/site-packages/psycopg2/__init__.py", line 126, in connect\n    conn = _connect(dsn, connection_factory=connection_factory, **kwasync)\n  File "/Users/rg/Dropbox/_code/python/envs/ccat_w_jupyter/lib/python3.7/site-packages/pgcli/pgexecute.py", line 40, in _wait_select\n    state = conn.poll()\npsycopg2.OperationalError: FATAL:  password authentication failed for user "root"\n\n'
2019-08-07 16:00:22,847 (5709/MainThread) pgcli.main INFO - Default pager found in PAGER environment variable: "less"
2019-08-07 16:00:22,847 (5709/MainThread) pgcli.main WARNING - import keyring failed: ModuleNotFoundError("No module named 'keyring'").
2019-08-07 16:00:30,694 (5709/MainThread) pgcli.main ERROR - traceback: 'Traceback (most recent call last):\n  File "/Users/rg/Dropbox/_code/python/envs/ccat_w_jupyter/lib/python3.7/site-packages/pgcli/main.py", line 556, in connect\n    pgexecute = PGExecute(database, user, passwd, host, port, dsn, **kwargs)\n  File "/Users/rg/Dropbox/_code/python/envs/ccat_w_jupyter/lib/python3.7/site-packages/pgcli/pgexecute.py", line 215, in __init__\n    self.connect(database, user, password, host, port, dsn, **kwargs)\n  File "/Users/rg/Dropbox/_code/python/envs/ccat_w_jupyter/lib/python3.7/site-packages/pgcli/pgexecute.py", line 267, in connect\n    conn = psycopg2.connect(**conn_params)\n  File "/Users/rg/Dropbox/_code/python/envs/ccat_w_jupyter/lib/python3.7/site-packages/psycopg2/__init__.py", line 126, in connect\n    conn = _connect(dsn, connection_factory=connection_factory, **kwasync)\n  File "/Users/rg/Dropbox/_code/python/envs/ccat_w_jupyter/lib/python3.7/site-packages/pgcli/pgexecute.py", line 40, in _wait_select\n    state = conn.poll()\npsycopg2.OperationalError: fe_sendauth: no password supplied\n\n\nDuring handling of the above exception, another exception occurred:\n\nTraceback (most recent call last):\n  File "/Users/rg/Dropbox/_code/python/envs/ccat_w_jupyter/lib/python3.7/site-packages/pgcli/main.py", line 566, in connect\n    database, user, passwd, host, port, dsn, **kwargs\n  File "/Users/rg/Dropbox/_code/python/envs/ccat_w_jupyter/lib/python3.7/site-packages/pgcli/pgexecute.py", line 215, in __init__\n    self.connect(database, user, password, host, port, dsn, **kwargs)\n  File "/Users/rg/Dropbox/_code/python/envs/ccat_w_jupyter/lib/python3.7/site-packages/pgcli/pgexecute.py", line 267, in connect\n    conn = psycopg2.connect(**conn_params)\n  File "/Users/rg/Dropbox/_code/python/envs/ccat_w_jupyter/lib/python3.7/site-packages/psycopg2/__init__.py", line 126, in connect\n    conn = _connect(dsn, connection_factory=connection_factory, **kwasync)\n  File "/Users/rg/Dropbox/_code/python/envs/ccat_w_jupyter/lib/python3.7/site-packages/pgcli/pgexecute.py", line 40, in _wait_select\n    state = conn.poll()\npsycopg2.OperationalError: FATAL:  password authentication failed for user "root"\n\n'
2019-08-07 16:01:03,056 (5731/MainThread) pgcli.main INFO - Default pager found in PAGER environment variable: "less"
2019-08-07 16:01:03,057 (5731/MainThread) pgcli.main WARNING - import keyring failed: ModuleNotFoundError("No module named 'keyring'").
2019-08-07 16:02:11,012 (5731/MainThread) pgcli.pgexecute ERROR - sql: 'c ccat', error: SyntaxError('syntax error at or near "c"\nLINE 1: c ccat\n        ^\n')
2019-08-07 16:02:11,014 (5731/MainThread) pgcli.pgexecute ERROR - traceback: 'Traceback (most recent call last):\n  File "/Users/rg/Dropbox/_code/python/envs/ccat_w_jupyter/lib/python3.7/site-packages/pgcli/pgexecute.py", line 402, in run\n    yield self.execute_normal_sql(sql) + (sql, True, False)\n  File "/Users/rg/Dropbox/_code/python/envs/ccat_w_jupyter/lib/python3.7/site-packages/pgcli/pgexecute.py", line 433, in execute_normal_sql\n    cur.execute(split_sql)\npsycopg2.errors.SyntaxError: syntax error at or near "c"\nLINE 1: c ccat\n        ^\n\n'
2019-08-19 14:13:47,056 (16696/MainThread) pgcli.main INFO - Default pager found in PAGER environment variable: "less"
2019-08-19 14:13:47,057 (16696/MainThread) pgcli.main WARNING - import keyring failed: ModuleNotFoundError("No module named 'keyring'").
2019-08-19 14:14:03,455 (16696/MainThread) pgcli.main ERROR - traceback: 'Traceback (most recent call last):\n  File "/Users/rg/Dropbox/_code/python/envs/ccat_w_jupyter/lib/python3.7/site-packages/pgcli/main.py", line 556, in connect\n    pgexecute = PGExecute(database, user, passwd, host, port, dsn, **kwargs)\n  File "/Users/rg/Dropbox/_code/python/envs/ccat_w_jupyter/lib/python3.7/site-packages/pgcli/pgexecute.py", line 215, in __init__\n    self.connect(database, user, password, host, port, dsn, **kwargs)\n  File "/Users/rg/Dropbox/_code/python/envs/ccat_w_jupyter/lib/python3.7/site-packages/pgcli/pgexecute.py", line 267, in connect\n    conn = psycopg2.connect(**conn_params)\n  File "/Users/rg/Dropbox/_code/python/envs/ccat_w_jupyter/lib/python3.7/site-packages/psycopg2/__init__.py", line 126, in connect\n    conn = _connect(dsn, connection_factory=connection_factory, **kwasync)\n  File "/Users/rg/Dropbox/_code/python/envs/ccat_w_jupyter/lib/python3.7/site-packages/pgcli/pgexecute.py", line 40, in _wait_select\n    state = conn.poll()\npsycopg2.OperationalError: fe_sendauth: no password supplied\n\n\nDuring handling of the above exception, another exception occurred:\n\nTraceback (most recent call last):\n  File "/Users/rg/Dropbox/_code/python/envs/ccat_w_jupyter/lib/python3.7/site-packages/pgcli/main.py", line 566, in connect\n    database, user, passwd, host, port, dsn, **kwargs\n  File "/Users/rg/Dropbox/_code/python/envs/ccat_w_jupyter/lib/python3.7/site-packages/pgcli/pgexecute.py", line 215, in __init__\n    self.connect(database, user, password, host, port, dsn, **kwargs)\n  File "/Users/rg/Dropbox/_code/python/envs/ccat_w_jupyter/lib/python3.7/site-packages/pgcli/pgexecute.py", line 267, in connect\n    conn = psycopg2.connect(**conn_params)\n  File "/Users/rg/Dropbox/_code/python/envs/ccat_w_jupyter/lib/python3.7/site-packages/psycopg2/__init__.py", line 126, in connect\n    conn = _connect(dsn, connection_factory=connection_factory, **kwasync)\n  File "/Users/rg/Dropbox/_code/python/envs/ccat_w_jupyter/lib/python3.7/site-packages/pgcli/pgexecute.py", line 40, in _wait_select\n    state = conn.poll()\npsycopg2.OperationalError: FATAL:  password authentication failed for user "root"\n\n'
2019-08-19 14:14:06,540 (16712/MainThread) pgcli.main INFO - Default pager found in PAGER environment variable: "less"
2019-08-19 14:14:06,541 (16712/MainThread) pgcli.main WARNING - import keyring failed: ModuleNotFoundError("No module named 'keyring'").
2019-08-19 14:14:16,639 (16712/MainThread) pgcli.main ERROR - traceback: 'Traceback (most recent call last):\n  File "/Users/rg/Dropbox/_code/python/envs/ccat_w_jupyter/lib/python3.7/site-packages/pgcli/main.py", line 556, in connect\n    pgexecute = PGExecute(database, user, passwd, host, port, dsn, **kwargs)\n  File "/Users/rg/Dropbox/_code/python/envs/ccat_w_jupyter/lib/python3.7/site-packages/pgcli/pgexecute.py", line 215, in __init__\n    self.connect(database, user, password, host, port, dsn, **kwargs)\n  File "/Users/rg/Dropbox/_code/python/envs/ccat_w_jupyter/lib/python3.7/site-packages/pgcli/pgexecute.py", line 267, in connect\n    conn = psycopg2.connect(**conn_params)\n  File "/Users/rg/Dropbox/_code/python/envs/ccat_w_jupyter/lib/python3.7/site-packages/psycopg2/__init__.py", line 126, in connect\n    conn = _connect(dsn, connection_factory=connection_factory, **kwasync)\n  File "/Users/rg/Dropbox/_code/python/envs/ccat_w_jupyter/lib/python3.7/site-packages/pgcli/pgexecute.py", line 40, in _wait_select\n    state = conn.poll()\npsycopg2.OperationalError: fe_sendauth: no password supplied\n\n\nDuring handling of the above exception, another exception occurred:\n\nTraceback (most recent call last):\n  File "/Users/rg/Dropbox/_code/python/envs/ccat_w_jupyter/lib/python3.7/site-packages/pgcli/main.py", line 566, in connect\n    database, user, passwd, host, port, dsn, **kwargs\n  File "/Users/rg/Dropbox/_code/python/envs/ccat_w_jupyter/lib/python3.7/site-packages/pgcli/pgexecute.py", line 215, in __init__\n    self.connect(database, user, password, host, port, dsn, **kwargs)\n  File "/Users/rg/Dropbox/_code/python/envs/ccat_w_jupyter/lib/python3.7/site-packages/pgcli/pgexecute.py", line 267, in connect\n    conn = psycopg2.connect(**conn_params)\n  File "/Users/rg/Dropbox/_code/python/envs/ccat_w_jupyter/lib/python3.7/site-packages/psycopg2/__init__.py", line 126, in connect\n    conn = _connect(dsn, connection_factory=connection_factory, **kwasync)\n  File "/Users/rg/Dropbox/_code/python/envs/ccat_w_jupyter/lib/python3.7/site-packages/pgcli/pgexecute.py", line 40, in _wait_select\n    state = conn.poll()\npsycopg2.OperationalError: FATAL:  password authentication failed for user "root"\n\n'
2019-08-19 14:14:41,333 (16727/MainThread) pgcli.main INFO - Default pager found in PAGER environment variable: "less"
2019-08-19 14:14:41,334 (16727/MainThread) pgcli.main WARNING - import keyring failed: ModuleNotFoundError("No module named 'keyring'").
2019-08-19 14:15:09,945 (16727/MainThread) pgcli.pgexecute ERROR - sql: 'c ccat', error: SyntaxError('syntax error at or near "c"\nLINE 1: c ccat\n        ^\n')
2019-08-19 14:15:09,947 (16727/MainThread) pgcli.pgexecute ERROR - traceback: 'Traceback (most recent call last):\n  File "/Users/rg/Dropbox/_code/python/envs/ccat_w_jupyter/lib/python3.7/site-packages/pgcli/pgexecute.py", line 402, in run\n    yield self.execute_normal_sql(sql) + (sql, True, False)\n  File "/Users/rg/Dropbox/_code/python/envs/ccat_w_jupyter/lib/python3.7/site-packages/pgcli/pgexecute.py", line 433, in execute_normal_sql\n    cur.execute(split_sql)\npsycopg2.errors.SyntaxError: syntax error at or near "c"\nLINE 1: c ccat\n        ^\n\n'
2019-08-19 14:15:15,546 (16727/MainThread) pgcli.pgexecute ERROR - sql: 'c\\ ccat', error: SyntaxError('syntax error at or near "c"\nLINE 1: c\\ ccat\n        ^\n')
2019-08-19 14:15:15,546 (16727/MainThread) pgcli.pgexecute ERROR - traceback: 'Traceback (most recent call last):\n  File "/Users/rg/Dropbox/_code/python/envs/ccat_w_jupyter/lib/python3.7/site-packages/pgcli/pgexecute.py", line 402, in run\n    yield self.execute_normal_sql(sql) + (sql, True, False)\n  File "/Users/rg/Dropbox/_code/python/envs/ccat_w_jupyter/lib/python3.7/site-packages/pgcli/pgexecute.py", line 433, in execute_normal_sql\n    cur.execute(split_sql)\npsycopg2.errors.SyntaxError: syntax error at or near "c"\nLINE 1: c\\ ccat\n        ^\n\n'
2019-08-19 16:28:09,538 (16727/MainThread) pgcli.pgexecute ERROR - sql: 'drop bitmex_test', error: SyntaxError('syntax error at or near "bitmex_test"\nLINE 1: drop bitmex_test\n             ^\n')
2019-08-19 16:28:09,545 (16727/MainThread) pgcli.pgexecute ERROR - traceback: 'Traceback (most recent call last):\n  File "/Users/rg/Dropbox/_code/python/envs/ccat_w_jupyter/lib/python3.7/site-packages/pgcli/pgexecute.py", line 402, in run\n    yield self.execute_normal_sql(sql) + (sql, True, False)\n  File "/Users/rg/Dropbox/_code/python/envs/ccat_w_jupyter/lib/python3.7/site-packages/pgcli/pgexecute.py", line 433, in execute_normal_sql\n    cur.execute(split_sql)\npsycopg2.errors.SyntaxError: syntax error at or near "bitmex_test"\nLINE 1: drop bitmex_test\n             ^\n\n'
2019-08-19 16:29:52,307 (16727/MainThread) pgcli.pgexecute ERROR - sql: 'delete bitmex_test', error: SyntaxError('syntax error at or near "bitmex_test"\nLINE 1: delete bitmex_test\n               ^\n')
2019-08-19 16:29:52,313 (16727/MainThread) pgcli.pgexecute ERROR - traceback: 'Traceback (most recent call last):\n  File "/Users/rg/Dropbox/_code/python/envs/ccat_w_jupyter/lib/python3.7/site-packages/pgcli/pgexecute.py", line 402, in run\n    yield self.execute_normal_sql(sql) + (sql, True, False)\n  File "/Users/rg/Dropbox/_code/python/envs/ccat_w_jupyter/lib/python3.7/site-packages/pgcli/pgexecute.py", line 433, in execute_normal_sql\n    cur.execute(split_sql)\npsycopg2.errors.SyntaxError: syntax error at or near "bitmex_test"\nLINE 1: delete bitmex_test\n               ^\n\n'
2019-08-19 16:30:07,236 (16727/MainThread) pgcli.pgexecute ERROR - sql: 'drop bitmex_test', error: SyntaxError('syntax error at or near "bitmex_test"\nLINE 1: drop bitmex_test\n             ^\n')
2019-08-19 16:30:07,236 (16727/MainThread) pgcli.pgexecute ERROR - traceback: 'Traceback (most recent call last):\n  File "/Users/rg/Dropbox/_code/python/envs/ccat_w_jupyter/lib/python3.7/site-packages/pgcli/pgexecute.py", line 402, in run\n    yield self.execute_normal_sql(sql) + (sql, True, False)\n  File "/Users/rg/Dropbox/_code/python/envs/ccat_w_jupyter/lib/python3.7/site-packages/pgcli/pgexecute.py", line 433, in execute_normal_sql\n    cur.execute(split_sql)\npsycopg2.errors.SyntaxError: syntax error at or near "bitmex_test"\nLINE 1: drop bitmex_test\n             ^\n\n'
2019-08-19 17:29:27,504 (16727/MainThread) pgcli.pgexecute ERROR - sql: "'d", error: SyntaxError('unterminated quoted string at or near "\'d"\nLINE 1: \'d\n        ^\n')
2019-08-19 17:29:27,505 (16727/MainThread) pgcli.pgexecute ERROR - traceback: 'Traceback (most recent call last):\n  File "/Users/rg/Dropbox/_code/python/envs/ccat_w_jupyter/lib/python3.7/site-packages/pgcli/pgexecute.py", line 402, in run\n    yield self.execute_normal_sql(sql) + (sql, True, False)\n  File "/Users/rg/Dropbox/_code/python/envs/ccat_w_jupyter/lib/python3.7/site-packages/pgcli/pgexecute.py", line 433, in execute_normal_sql\n    cur.execute(split_sql)\npsycopg2.errors.SyntaxError: unterminated quoted string at or near "\'d"\nLINE 1: \'d\n        ^\n\n'
2019-08-22 14:04:01,149 (35523/MainThread) pgcli.main INFO - Default pager found in PAGER environment variable: "less"
2019-08-22 14:04:01,150 (35523/MainThread) pgcli.main WARNING - import keyring failed: ModuleNotFoundError("No module named 'keyring'").
2019-08-30 14:37:12,780 (70532/MainThread) pgcli.main INFO - Default pager found in PAGER environment variable: "less"
2019-08-30 14:37:12,781 (70532/MainThread) pgcli.main WARNING - import keyring failed: ModuleNotFoundError("No module named 'keyring'").
2019-08-30 14:39:28,664 (70532/MainThread) pgcli.pgexecute ERROR - sql: 'ALTER USER postgres PASSWORD ")p6B,&<5&\'3xqM+Q"', error: SyntaxError('syntax error at or near "")p6B,&<5&\'3xqM+Q""\nLINE 1: ALTER USER postgres PASSWORD ")p6B,&<5&\'3xqM+Q"\n                                     ^\n')
2019-08-30 14:39:28,670 (70532/MainThread) pgcli.pgexecute ERROR - traceback: 'Traceback (most recent call last):\n  File "/Users/rg/Dropbox/_code/python/envs/ccat_w_jupyter/lib/python3.7/site-packages/pgcli/pgexecute.py", line 402, in run\n    yield self.execute_normal_sql(sql) + (sql, True, False)\n  File "/Users/rg/Dropbox/_code/python/envs/ccat_w_jupyter/lib/python3.7/site-packages/pgcli/pgexecute.py", line 433, in execute_normal_sql\n    cur.execute(split_sql)\npsycopg2.errors.SyntaxError: syntax error at or near "")p6B,&<5&\'3xqM+Q""\nLINE 1: ALTER USER postgres PASSWORD ")p6B,&<5&\'3xqM+Q"\n                                     ^\n\n'
2019-08-30 14:39:52,684 (70532/MainThread) pgcli.pgexecute ERROR - sql: "ALTER USER postgres PASSWORD )p6B,&<5&'3xqM+Q", error: SyntaxError('syntax error at or near ")"\nLINE 1: ALTER USER postgres PASSWORD )p6B,&<5&\'3xqM+Q\n                                     ^\n')
2019-08-30 14:39:52,684 (70532/MainThread) pgcli.pgexecute ERROR - traceback: 'Traceback (most recent call last):\n  File "/Users/rg/Dropbox/_code/python/envs/ccat_w_jupyter/lib/python3.7/site-packages/pgcli/pgexecute.py", line 402, in run\n    yield self.execute_normal_sql(sql) + (sql, True, False)\n  File "/Users/rg/Dropbox/_code/python/envs/ccat_w_jupyter/lib/python3.7/site-packages/pgcli/pgexecute.py", line 433, in execute_normal_sql\n    cur.execute(split_sql)\npsycopg2.errors.SyntaxError: syntax error at or near ")"\nLINE 1: ALTER USER postgres PASSWORD )p6B,&<5&\'3xqM+Q\n                                     ^\n\n'
2019-08-30 14:41:46,839 (70532/MainThread) pgcli.pgexecute ERROR - sql: "ALTER USER postgres WITH PASSWORD ')p6B,&<5&'3xqM+Q'", error: SyntaxError('syntax error at or near "3"\nLINE 1: ALTER USER postgres WITH PASSWORD \')p6B,&<5&\'3xqM+Q\'\n                                                     ^\n')
2019-08-30 14:41:46,839 (70532/MainThread) pgcli.pgexecute ERROR - traceback: 'Traceback (most recent call last):\n  File "/Users/rg/Dropbox/_code/python/envs/ccat_w_jupyter/lib/python3.7/site-packages/pgcli/pgexecute.py", line 402, in run\n    yield self.execute_normal_sql(sql) + (sql, True, False)\n  File "/Users/rg/Dropbox/_code/python/envs/ccat_w_jupyter/lib/python3.7/site-packages/pgcli/pgexecute.py", line 433, in execute_normal_sql\n    cur.execute(split_sql)\npsycopg2.errors.SyntaxError: syntax error at or near "3"\nLINE 1: ALTER USER postgres WITH PASSWORD \')p6B,&<5&\'3xqM+Q\'\n                                                     ^\n\n'
2019-08-30 14:42:02,780 (70532/MainThread) pgcli.pgexecute ERROR - sql: 'ALTER USER postgres WITH PASSWORD ")p6B,&<5&\'3xqM+Q"', error: SyntaxError('syntax error at or near "")p6B,&<5&\'3xqM+Q""\nLINE 1: ALTER USER postgres WITH PASSWORD ")p6B,&<5&\'3xqM+Q"\n                                          ^\n')
2019-08-30 14:42:02,781 (70532/MainThread) pgcli.pgexecute ERROR - traceback: 'Traceback (most recent call last):\n  File "/Users/rg/Dropbox/_code/python/envs/ccat_w_jupyter/lib/python3.7/site-packages/pgcli/pgexecute.py", line 402, in run\n    yield self.execute_normal_sql(sql) + (sql, True, False)\n  File "/Users/rg/Dropbox/_code/python/envs/ccat_w_jupyter/lib/python3.7/site-packages/pgcli/pgexecute.py", line 433, in execute_normal_sql\n    cur.execute(split_sql)\npsycopg2.errors.SyntaxError: syntax error at or near "")p6B,&<5&\'3xqM+Q""\nLINE 1: ALTER USER postgres WITH PASSWORD ")p6B,&<5&\'3xqM+Q"\n                                          ^\n\n'
2019-08-30 14:42:30,794 (70532/MainThread) pgcli.pgexecute ERROR - sql: 'ALTER USER postgres WITH PASSWORD "V7g934UyjAht8sgC"', error: SyntaxError('syntax error at or near ""V7g934UyjAht8sgC""\nLINE 1: ALTER USER postgres WITH PASSWORD "V7g934UyjAht8sgC"\n                                          ^\n')
2019-08-30 14:42:30,794 (70532/MainThread) pgcli.pgexecute ERROR - traceback: 'Traceback (most recent call last):\n  File "/Users/rg/Dropbox/_code/python/envs/ccat_w_jupyter/lib/python3.7/site-packages/pgcli/pgexecute.py", line 402, in run\n    yield self.execute_normal_sql(sql) + (sql, True, False)\n  File "/Users/rg/Dropbox/_code/python/envs/ccat_w_jupyter/lib/python3.7/site-packages/pgcli/pgexecute.py", line 433, in execute_normal_sql\n    cur.execute(split_sql)\npsycopg2.errors.SyntaxError: syntax error at or near ""V7g934UyjAht8sgC""\nLINE 1: ALTER USER postgres WITH PASSWORD "V7g934UyjAht8sgC"\n                                          ^\n\n'
2019-08-30 14:43:18,073 (70560/MainThread) pgcli.main INFO - Default pager found in PAGER environment variable: "less"
2019-08-30 14:43:18,073 (70560/MainThread) pgcli.main WARNING - import keyring failed: ModuleNotFoundError("No module named 'keyring'").
